Workbook

Sheet Dashboard
A2: Football forward performance
A4: Only verified 90-minute results settle a selection. Win rate = wins / settled selections.
A6: Metric | B6: Result | D6: Tier | E6: Settled | F6: Win rate
A7: Archived selections | B7: =Breakdowns!C6 -> 22 | D7: STRICT | E7: =Breakdowns!D7 -> 6 | F7: =Breakdowns!H7 -> 1
A8: Settled selections | B8: =Breakdowns!D6 -> 11 | D8: PROVISIONAL | E8: =Breakdowns!D8 -> 5 | F8: =Breakdowns!H8 -> 0.4
A9: Wins | B9: =Breakdowns!E6 -> 8
A10: Losses | B10: =Breakdowns!F6 -> 3 | D10: Evidence status
A11: Pending / unverified | B11: =Breakdowns!G6 -> 11 | D11: =IF(B8=0,"Awaiting verified results",IF(B8<30,"Early sample: continue forward testing","Review calibration and ROI by segment")) -> Early sample: continue forward testing
A12: Win rate | B12: =Breakdowns!H6 -> 0.72727273
A13: Simulated flat-stake ROI | B13: =Breakdowns!K6 -> 0.01 | D13: Results coverage
A14: Simulated net profit (units) | B14: =Breakdowns!J6 -> 0.11 | D14: 11 settled; 11 pending / unverified
A15: Selection Brier (lower is better) | B15: =Breakdowns!L6 -> 0.21593197
A16: 1X2 forecast accuracy | B16: =IF(COUNT(Predictions!H6:H147)=0,"n.a.",AVERAGE(Predictions!H6:H147)) -> 0.64705882 | D16: Forecast metric | E16: Samples | F16: Accuracy
A17: 1X2 multiclass Brier | B17: =IF(COUNT(Predictions!I6:I147)=0,"n.a.",AVERAGE(Predictions!I6:I147)) -> 0.54248256 | D17: Over 1.5 | E17: =COUNT(Predictions!J6:J147) -> 34 | F17: =IF(E17=0,"n.a.",AVERAGE(Predictions!J6:J147)) -> 0.91176471
A18: Win-rate 95% lower | B18: =IF(B8=0,"n.a.",(B12+1.96^2/(2*B8)-1.96*SQRT(B12*(1-B12)/B8+1.96^2/(4*B8^2)))/(1+1.96^2/B8)) -> 0.43434971 | D18: Under 3.5 | E18: =COUNT(Predictions!K6:K147) -> 34 | F18: =IF(E18=0,"n.a.",AVERAGE(Predictions!K6:K147)) -> 0.55882353
A19: Win-rate 95% upper | B19: =IF(B8=0,"n.a.",(B12+1.96^2/(2*B8)+1.96*SQRT(B12*(1-B12)/B8+1.96^2/(4*B8^2)))/(1+1.96^2/B8)) -> 0.90254119 | D19: BTTS Yes | E19: =COUNT(Predictions!L6:L147) -> 34 | F19: =IF(E19=0,"n.a.",AVERAGE(Predictions!L6:L147)) -> 0.52941176
D20: BTTS No | E20: =COUNT(Predictions!M6:M147) -> 34 | F20: =IF(E20=0,"n.a.",AVERAGE(Predictions!M6:M147)) -> 0.52941176
A21: Conclusion: 8 wins from 11 settled selections. Early evidence; do not retune from this sample.
A23: ROI Plan: editable bankroll and flat stake. ROI excludes settled entries with missing odds.
A24: Model review: compare tiers, markets, leagues and policies in Breakdowns. Decisions remain manual.
A25: Weeks use the ISO calendar, not competition matchweek numbers.
A26: Result-source issues: none recorded
A27: Review UTC: 2026-10-15T15:13:16.300635+00:00
A28: PROVISIONAL is a research watchlist. Positive simulated ROI does not establish profitability.
A29: Review notes use 30 scored samples as a prompt, not statistical proof. Reassess on a future holdout.
A31: Experiment readiness | D31: Collection health
A33: Monitoring and next actions
A34: Check | B34: Status | D34: Next action
A35: Experiments ready | B35: 0 | D35: Continue generating and pushing forecasts
A36: Unavailable / stale reports | B36: 0 | D36: No stale experiment reports recorded
A37: Missing near-close quotes | B37: 25 | D37: Check local collection and push quotes; counts overlap across bookmakers
A38: Rejected quote files | B38: 0 | D38: No rejected quote files recorded
A39: Latest frozen capture | B39: 2026-10-15 13:21:36 UTC | D39: See Capture Details for all six experiment states
A41: Weekly samples and profit | D41: Metric definitions

Sheet Experiments
A2: Experiment readiness
A4: Readiness invites review, including negative findings. Production changes still require approval.
A5: Experiment | B5: Status | C5: Collected | D5: Evidence unit | E5: Required sample | F5: Time collected / required | G5: Verified coverage | H5: Review scope | I5: Remaining requirements / next action | J5: Evidence finding
A6: Goal-market blend | B6: Collect more data | C6: 48 | D6: Settled observations | E6: 30 settled observations | F6: 2 / 28 days | G6: Not applicable | H6: Initial review only | I6: 26 more days | J6: Initial review only
A7: Market-led forecasts | B7: Collect more data | C7: 32 | D7: Settled observations | E7: 30 settled observations | F7: 2 / 28 days | G7: Not applicable | H7: Initial review only | I7: 26 more days | J7: Initial review only
A8: Recency comparison | B8: Collect more data | C8: 30 | D8: Settled observations | E8: 30 settled observations | F8: 1 / 28 days | G8: Not applicable | H8: Initial review only | I8: 27 more days | J8: Initial review only
A9: EV filter sensitivity | B9: Collect more data | C9: 3 | D9: Settled observations | E9: 30 settled observations | F9: 1 / 28 days | G9: Not applicable | H9: Initial review only | I9: 27 more observations; 27 more days | J9: Initial review only
A10: 85% market weight | B10: Collect more data | C10: 0 | D10: Paired fixtures | E10: 300 paired fixtures | F10: 0 / 6 ISO weeks | G10: Unavailable | H10: Approval review | I10: 300 more paired fixtures; 6 more ISO weeks; Verified coverage unavailable | J10: No clear promotion evidence
A11: Pinnacle totals anchor | B11: Collect more data | C11: 0 | D11: Paired fixtures | E11: 300 paired fixtures | F11: 0 / 6 ISO weeks | G11: Unavailable | H11: Approval review | I11: 300 more paired fixtures; 6 more ISO weeks; Verified coverage unavailable | J11: No clear promotion evidence
A12: Stronger regularisation (L2=3) | B12: Collect more data | C12: 0 | D12: Paired fixtures | E12: 300 paired fixtures | F12: 0 / 6 ISO weeks | G12: Unavailable | H12: Approval review | I12: 300 more paired fixtures; 6 more ISO weeks; Verified coverage unavailable | J12: No clear promotion evidence
A13: Fixed half-life (480 days) | B13: Collect more data | C13: 0 | D13: Paired fixtures | E13: 300 paired fixtures | F13: 0 / 6 ISO weeks | G13: Unavailable | H13: Approval review | I13: 300 more paired fixtures; 6 more ISO weeks; Verified coverage unavailable | J13: No clear promotion evidence
A14: Probability / calibration policy | B14: Collect more data | C14: 0 | D14: Paired fixtures | E14: 300 paired fixtures | F14: 0 / 6 ISO weeks | G14: 0 | H14: Approval review | I14: 300 more paired fixtures; 6 more ISO weeks; Coverage below 80% | J14: Initial review only
A16: The original four sidecars count observations, not necessarily independent fixtures. Do not add their sample counts together.
A17: Coverage and time gates must also pass. Reaching a sample count alone does not make a candidate ready.
A19: Back to dashboard
A22: Probability and calibration policies — fixed comparisons
A23: STRICT is primary. ROI is simulated; different selected cohorts are not paired forecast tests. See the detailed report before drawing conclusions.
A24: Variant | B24: Tier | C24: Selected | D24: Settled | E24: Net ROI | F24: Brier | G24: Log loss | H24: Calibration gap | I24: Drawdown (units) | J24: Strict profit delta / fixture 95% interval
A25: control | B25: STRICT | C25: 1 | D25: 0 | E25: Unavailable | F25: Unavailable | G25: Unavailable | H25: Unavailable | I25: Unavailable | J25: Collect more data
A26: control | B26: PROVISIONAL | C26: 1 | D26: 0 | E26: Unavailable | F26: Unavailable | G26: Unavailable | H26: Unavailable | I26: Unavailable | J26: Not applicable
A27: control | B27: ALL | C27: 2 | D27: 0 | E27: Unavailable | F27: Unavailable | G27: Unavailable | H27: Unavailable | I27: Unavailable | J27: Not applicable
A28: blended_lower | B28: STRICT | C28: 3 | D28: 0 | E28: Unavailable | F28: Unavailable | G28: Unavailable | H28: Unavailable | I28: Unavailable | J28: Collect more data
A29: blended_lower | B29: PROVISIONAL | C29: 1 | D29: 0 | E29: Unavailable | F29: Unavailable | G29: Unavailable | H29: Unavailable | I29: Unavailable | J29: Not applicable
A30: blended_lower | B30: ALL | C30: 4 | D30: 0 | E30: Unavailable | F30: Unavailable | G30: Unavailable | H30: Unavailable | I30: Unavailable | J30: Not applicable
A31: blended_higher | B31: STRICT | C31: 0 | D31: 0 | E31: Unavailable | F31: Unavailable | G31: Unavailable | H31: Unavailable | I31: Unavailable | J31: Collect more data
A32: blended_higher | B32: PROVISIONAL | C32: 1 | D32: 0 | E32: Unavailable | F32: Unavailable | G32: Unavailable | H32: Unavailable | I32: Unavailable | J32: Not applicable
A33: blended_higher | B33: ALL | C33: 1 | D33: 0 | E33: Unavailable | F33: Unavailable | G33: Unavailable | H33: Unavailable | I33: Unavailable | J33: Not applicable
A34: raw_lower | B34: STRICT | C34: 1 | D34: 0 | E34: Unavailable | F34: Unavailable | G34: Unavailable | H34: Unavailable | I34: Unavailable | J34: Collect more data
A35: raw_lower | B35: PROVISIONAL | C35: 1 | D35: 0 | E35: Unavailable | F35: Unavailable | G35: Unavailable | H35: Unavailable | I35: Unavailable | J35: Not applicable
A36: raw_lower | B36: ALL | C36: 2 | D36: 0 | E36: Unavailable | F36: Unavailable | G36: Unavailable | H36: Unavailable | I36: Unavailable | J36: Not applicable
... A51: penalty_stronger | B51: ALL | C51: 2 | D51: 0 | E51: Unavailable | F51: Unavailable | G51: Unavailable | H51: Unavailable | I51: Unavailable | J51: Not applicable

Sheet Pipeline Health
A2: Pipeline health
A4: Health describes collection and evidence coverage. Recent result dates alone do not verify source completeness.
A5: Review UTC: 2026-10-15T15:13:16.300635+00:00
A7: Training data freshness
A8: League | B8: Latest result | C8: Training matches | D8: Days since result | E8: Source status | F8: Next check
A9: Bundesliga | B9: 2026-10-11 | C9: 963 | D9: 4 | E9: Result date only not completeness verified | F9: Source completeness unverified
A10: EPL | B10: 2026-10-12 | C10: 1200 | D10: 3 | E10: Result date only not completeness verified | F10: Source completeness unverified
A11: LaLiga | B11: 2026-10-12 | C11: 1218 | D11: 3 | E11: Result date only not completeness verified | F11: Source completeness unverified
A12: Ligue1 | B12: 2026-10-11 | C12: 972 | D12: 4 | E12: Result date only not completeness verified | F12: Source completeness unverified
A13: SerieA | B13: 2026-10-12 | C13: 1200 | D13: 3 | E13: Result date only not completeness verified | F13: Source completeness unverified
A14: UCL | B14: 2026-10-14 | C14: 539 | D14: 1 | E14: Current within provider schedule | F14: See source health report
A17: Near-close quote coverage
A18: Bookmaker | B18: Covered selections | C18: Missing selections | D18: Pending selections | E18: Mean fair-close EV | F18: Same-book offer CLV
A19: 1xbet | B19: 0 | C19: 13 | D19: 9 | E19: Unavailable | F19: Unavailable
A20: pinnacle | B20: 1 | C20: 12 | D20: 9 | E20: 0.053178845 | F20: Unavailable
A23: Observed near-close quotes are not guaranteed official closes. Accepted bet prices and execution remain unverified.
A25: Latest shortlist quote audit
A26: Check | B26: Recorded value
A27: Account availability | B27: Not verified with bookmaker accounts
A28: Bookmakers: 1xBet | B28: 2
A29: Costs recorded | B29: 2
A30: Exchange quotes | B30: 0
A31: Missing quote age | B31: 0
A32: Quote age over 24h | B32: 0
A33: Selected quotes | B33: 2
A36: Forecast capture coverage
A37: Experiment | B37: Capture state | C37: Snapshot count
A38: Goal-market blend | B38: Captured | C38: 14
A39: Goal-market blend | B39: Legacy not recorded | C39: 14
A40: Market-led forecasts | B40: Captured | C40: 14
A41: Market-led forecasts | B41: Legacy not recorded | C41: 14
A42: Recency comparison | B42: Captured | C42: 10
A43: Recency comparison | B43: Legacy not recorded | C43: 18
A44: EV filter sensitivity | B44: Captured | C44: 9
A45: EV filter sensitivity | B45: Legacy not recorded | C45: 19
A46: 85% market weight | B46: Captured | C46: 7
A47: 85% market weight | B47: Legacy not recorded | C47: 20
A48: 85% market weight | B48: Present but rejected | C48: 1
A49: Pinnacle totals anchor | B49: Captured | C49: 7
... A55: Probability / calibration policy | B55: Present but rejected | C55: 1
...

Sheet Weekly Trends
A2: Weekly performance
A4: ISO calendar weeks. All archived selection policies and tiers; profit uses offered prices and simulated stakes.
A5: ISO week | B5: Settled selections | C5: Priced selections | D5: Simulated profit (units) | E5: Cumulative profit (units) | F5: Win rate
A6: =Breakdowns!B24 -> 2026-W41 | B6: =Breakdowns!D24 -> 4 | C6: =COUNTIFS(Selections!$P$6:$P$27,A6,Selections!$M$6:$M$27,">0") -> 4 | D6: =IF(C6=0,"n.a.",Breakdowns!J24) -> -1.48 | E6: =IF(SUM($C$6:C6)=0,"n.a.",SUM($D$6:D6)) -> -1.48 | F6: =Breakdowns!H24 -> 0.5
A7: =Breakdowns!B25 -> 2026-W42 | B7: =Breakdowns!D25 -> 7 | C7: =COUNTIFS(Selections!$P$6:$P$27,A7,Selections!$M$6:$M$27,">0") -> 7 | D7: =IF(C7=0,"n.a.",Breakdowns!J25) -> 1.59 | E7: =IF(SUM($C$6:C7)=0,"n.a.",SUM($D$6:D7)) -> 0.11 | F7: =Breakdowns!H25 -> 0.85714286
A8: =Breakdowns!B26 -> 2026-W43 | B8: =Breakdowns!D26 -> 0 | C8: =COUNTIFS(Selections!$P$6:$P$27,A8,Selections!$M$6:$M$27,">0") -> 0 | D8: =IF(C8=0,"n.a.",Breakdowns!J26) -> n.a. | E8: =IF(SUM($C$6:C8)=0,"n.a.",SUM($D$6:D8)) -> 0.11 | F8: =Breakdowns!H26 -> n.a.
A10: Pending selections are excluded from rates. Weeks with no priced settled selections have no realised evidence of profit.

Sheet Breakdowns
A2: Breakdowns
A4: Calculated from the archived selection ledger. Pending outcomes are excluded from rates.
A5: Dimension | B5: Group | C5: Archived | D5: Settled | E5: Wins | F5: Losses | G5: Pending | H5: Win rate | I5: Staked units | J5: Profit units | K5: ROI | L5: Brier | M5: Mean forecast | N5: Observed rate | O5: Calibration gap | P5: Probability samples | Q5: Review
A6: All | B6: All selections | C6: =COUNTA(Selections!$A$6:$A$27) -> 22 | D6: =(COUNTIFS(Selections!$K$6:$K$27,"WON")+COUNTIFS(Selections!$K$6:$K$27,"LOST")) -> 11 | E6: =COUNTIFS(Selections!$K$6:$K$27,"WON") -> 8 | F6: =COUNTIFS(Selections!$K$6:$K$27,"LOST") -> 3 | G6: =COUNTA(Selections!$A$6:$A$27)-(COUNTIFS(Selections!$K$6:$K$27,"WON")+COUNTIFS(Selections!$K$6:$K$27,"LOST")) -> 11 | H6: =IF((COUNTIFS(Selections!$K$6:$K$27,"WON")+COUNTIFS(Selections!$K$6:$K$27,"LOST"))=0,"n.a.",COUNTIFS(Selections!$K$6:$K$27,"WON")/(COUNTIFS(Selections!$K$6:$K$27,"WON")+COUNTIFS(Selections!$K$6:$K$27,"LOST"))) -> 0.72727273 | I6: =SUM(Selections!$M$6:$M$27) -> 11 | J6: =SUM(Selections!$N$6:$N$27) -> 0.11 | K6: =IF(SUM(Selections!$M$6:$M$27)=0,"n.a.",SUM(Selections!$N$6:$N$27)/SUM(Selections!$M$6:$M$27)) -> 0.01 | L6: =IF(SUM(Selections!$T$6:$T$27)=0,"n.a.",SUM(Selections!$O$6:$O$27)/SUM(Selections!$T$6:$T$27)) -> 0.21593197 | M6: =IF(SUM(Selections!$T$6:$T$27)=0,"n.a.",SUM(Selections!$S$6:$S$27)/SUM(Selections!$T$6:$T$27)) -> 0.80129825 | N6: =IF(SUM(Selections!$T$6:$T$27)=0,"n.a.",(SUMIFS(Selections!$L$6:$L$27,Selections!$T$6:$T$27,1))/SUM(Selections!$T$6:$T$27)) -> 0.72727273 | O6: =IF(SUM(Selections!$T$6:$T$27)=0,"n.a.",(SUM(Selections!$S$6:$S$27)-(SUMIFS(Selections!$L$6:$L$27,Selections!$T$6:$T$27,1)))/SUM(Selections!$T$6:$T$27)) -> 0.074025523 | P6: =SUM(Selections!$T$6:$T$27) -> 11 | Q6: =IF(P6<30,"Collect more scored forecasts (n="&P6&").",IF(O6>0.1,"Review overconfidence on a future holdout.",IF(K6<0,"Review prices and EV on a future holdout.","Continue forward testing. No automatic model change."))) -> Collect more scored forecasts (n=11).
A7: Tier | B7: STRICT | C7: =COUNTIFS(Selections!$F$6:$F$27,"STRICT") -> 12 | D7: =(COUNTIFS(Selections!$F$6:$F$27,"STRICT",Selections!$K$6:$K$27,"WON")+COUNTIFS(Selections!$F$6:$F$27,"STRICT",Selections!$K$6:$K$27,"LOST")) -> 6 | E7: =COUNTIFS(Selections!$F$6:$F$27,"STRICT",Selections!$K$6:$K$27,"WON") -> 6 | F7: =COUNTIFS(Selections!$F$6:$F$27,"STRICT",Selections!$K$6:$K$27,"LOST") -> 0 | G7: =COUNTIFS(Selections!$F$6:$F$27,"STRICT")-(COUNTIFS(Selections!$F$6:$F$27,"STRICT",Selections!$K$6:$K$27,"WON")+COUNTIFS(Selections!$F$6:$F$27,"STRICT",Selections!$K$6:$K$27,"LOST")) -> 6 | H7: =IF((COUNTIFS(Selections!$F$6:$F$27,"STRICT",Selections!$K$6:$K$27,"WON")+COUNTIFS(Selections!$F$6:$F$27,"STRICT",Selections!$K$6:$K$27,"LOST"))=0,"n.a.",COUNTIFS(Selections!$F$6:$F$27,"STRICT",Selections!$K$6:$K$27,"WON")/(COUNTIFS(Selections!$F$6:$F$27,"STRICT",Selections!$K$6:$K$27,"WON")+COUNTIFS(Selections!$F$6:$F$27,"STRICT",Selections!$K$6:$K$27,"LOST"))) -> 1 | I7: =SUMIFS(Selections!$M$6:$M$27,Selections!$F$6:$F$27,"STRICT") -> 6 | J7: =SUMIFS(Selections!$N$6:$N$27,Selections!$F$6:$F$27,"STRICT") -> 2.59 | K7: =IF(SUMIFS(Selections!$M$6:$M$27,Selections!$F$6:$F$27,"STRICT")=0,"n.a.",SUMIFS(Selections!$N$6:$N$27,Selections!$F$6:$F$27,"STRICT")/SUMIFS(Selections!$M$6:$M$27,Selections!$F$6:$F$27,"STRICT")) -> 0.43166667 | L7: =IF(SUMIFS(Selections!$T$6:$T$27,Selections!$F$6:$F$27,"STRICT")=0,"n.a.",SUMIFS(Selections!$O$6:$O$27,Selections!$F$6:$F$27,"STRICT")/SUMIFS(Selections!$T$6:$T$27,Selections!$F$6:$F$27,"STRICT")) -> 0.05977136 | M7: =IF(SUMIFS(Selections!$T$6:$T$27,Selections!$F$6:$F$27,"STRICT")=0,"n.a.",SUMIFS(Selections!$S$6:$S$27,Selections!$F$6:$F$27,"STRICT")/SUMIFS(Selections!$T$6:$T$27,Selections!$F$6:$F$27,"STRICT")) -> 0.78215519 | N7: =IF(SUMIFS(Selections!$T$6:$T$27,Selections!$F$6:$F$27,"STRICT")=0,"n.a.",(SUMIFS(Selections!$L$6:$L$27,Selections!$F$6:$F$27,"STRICT",Selections!$T$6:$T$27,1))/SUMIFS(Selections!$T$6:$T$27,Selections!$F$6:$F$27,"STRICT")) -> 1 | O7: =IF(SUMIFS(Selections!$T$6:$T$27,Selections!$F$6:$F$27,"STRICT")=0,"n.a.",(SUMIFS(Selections!$S$6:$S$27,Selections!$F$6:$F$27,"STRICT")-(SUMIFS(Selections!$L$6:$L$27,Selections!$F$6:$F$27,"STRICT",Selections!$T$6:$T$27,1)))/SUMIFS(Selections!$T$6:$T$27,Selections!$F$6:$F$27,"STRICT")) -> -0.21784481 | P7: =SUMIFS(Selections!$T$6:$T$27,Selections!$F$6:$F$27,"STRICT") -> 6 | Q7: =IF(P7<30,"Collect more scored forecasts (n="&P7&").",IF(O7>0.1,"Review overconfidence on a future holdout.",IF(K7<0,"Review prices and EV on a future holdout.","Continue forward testing. No automatic model change."))) -> Collect more scored forecasts (n=6).
A8: Tier | B8: PROVISIONAL | C8: =COUNTIFS(Selections!$F$6:$F$27,"PROVISIONAL") -> 10 | D8: =(COUNTIFS(Selections!$F$6:$F$27,"PROVISIONAL",Selections!$K$6:$K$27,"WON")+COUNTIFS(Selections!$F$6:$F$27,"PROVISIONAL",Selections!$K$6:$K$27,"LOST")) -> 5 | E8: =COUNTIFS(Selections!$F$6:$F$27,"PROVISIONAL",Selections!$K$6:$K$27,"WON") -> 2 | F8: =COUNTIFS(Selections!$F$6:$F$27,"PROVISIONAL",Selections!$K$6:$K$27,"LOST") -> 3 | G8: =COUNTIFS(Selections!$F$6:$F$27,"PROVISIONAL")-(COUNTIFS(Selections!$F$6:$F$27,"PROVISIONAL",Selections!$K$6:$K$27,"WON")+COUNTIFS(Selections!$F$6:$F$27,"PROVISIONAL",Selections!$K$6:$K$27,"LOST")) -> 5 | H8: =IF((COUNTIFS(Selections!$F$6:$F$27,"PROVISIONAL",Selections!$K$6:$K$27,"WON")+COUNTIFS(Selections!$F$6:$F$27,"PROVISIONAL",Selections!$K$6:$K$27,"LOST"))=0,"n.a.",COUNTIFS(Selections!$F$6:$F$27,"PROVISIONAL",Selections!$K$6:$K$27,"WON")/(COUNTIFS(Selections!$F$6:$F$27,"PROVISIONAL",Selections!$K$6:$K$27,"WON")+COUNTIFS(Selections!$F$6:$F$27,"PROVISIONAL",Selections!$K$6:$K$27,"LOST"))) -> 0.4 | I8: =SUMIFS(Selections!$M$6:$M$27,Selections!$F$6:$F$27,"PROVISIONAL") -> 5 | J8: =SUMIFS(Selections!$N$6:$N$27,Selections!$F$6:$F$27,"PROVISIONAL") -> -2.48 | K8: =IF(SUMIFS(Selections!$M$6:$M$27,Selections!$F$6:$F$27,"PROVISIONAL")=0,"n.a.",SUMIFS(Selections!$N$6:$N$27,Selections!$F$6:$F$27,"PROVISIONAL")/SUMIFS(Selections!$M$6:$M$27,Selections!$F$6:$F$27,"PROVISIONAL")) -> -0.496 | L8: =IF(SUMIFS(Selections!$T$6:$T$27,Selections!$F$6:$F$27,"PROVISIONAL")=0,"n.a.",SUMIFS(Selections!$O$6:$O$27,Selections!$F$6:$F$27,"PROVISIONAL")/SUMIFS(Selections!$T$6:$T$27,Selections!$F$6:$F$27,"PROVISIONAL")) -> 0.40332469 | M8: =IF(SUMIFS(Selections!$T$6:$T$27,Selections!$F$6:$F$27,"PROVISIONAL")=0,"n.a.",SUMIFS(Selections!$S$6:$S$27,Selections!$F$6:$F$27,"PROVISIONAL")/SUMIFS(Selections!$T$6:$T$27,Selections!$F$6:$F$27,"PROVISIONAL")) -> 0.82426992 | N8: =IF(SUMIFS(Selections!$T$6:$T$27,Selections!$F$6:$F$27,"PROVISIONAL")=0,"n.a.",(SUMIFS(Selections!$L$6:$L$27,Selections!$F$6:$F$27,"PROVISIONAL",Selections!$T$6:$T$27,1))/SUMIFS(Selections!$T$6:$T$27,Selections!$F$6:$F$27,"PROVISIONAL")) -> 0.4 | O8: =IF(SUMIFS(Selections!$T$6:$T$27,Selections!$F$6:$F$27,"PROVISIONAL")=0,"n.a.",(SUMIFS(Selections!$S$6:$S$27,Selections!$F$6:$F$27,"PROVISIONAL")-(SUMIFS(Selections!$L$6:$L$27,Selections!$F$6:$F$27,"PROVISIONAL",Selections!$T$6:$T$27,1)))/SUMIFS(Selections!$T$6:$T$27,Selections!$F$6:$F$27,"PROVISIONAL")) -> 0.42426992 | P8: =SUMIFS(Selections!$T$6:$T$27,Selections!$F$6:$F$27,"PROVISIONAL") -> 5 | Q8: =IF(P8<30,"Collect more scored forecasts (n="&P8&").",IF(O8>0.1,"Review overconfidence on a future holdout.",IF(K8<0,"Review prices and EV on a future holdout.","Continue forward testing. No automatic model change."))) -> Collect more scored forecasts (n=5).
A9: League | B9: Bundesliga | C9: =COUNTIFS(Selections!$C$6:$C$27,"Bundesliga") -> 1 | D9: =(COUNTIFS(Selections!$C$6:$C$27,"Bundesliga",Selections!$K$6:$K$27,"WON")+COUNTIFS(Selections!$C$6:$C$27,"Bundesliga",Selections!$K$6:$K$27,"LOST")) -> 0 | E9: =COUNTIFS(Selections!$C$6:$C$27,"Bundesliga",Selections!$K$6:$K$27,"WON") -> 0 | F9: =COUNTIFS(Selections!$C$6:$C$27,"Bundesliga",Selections!$K$6:$K$27,"LOST") -> 0 | G9: =COUNTIFS(Selections!$C$6:$C$27,"Bundesliga")-(COUNTIFS(Selections!$C$6:$C$27,"Bundesliga",Selections!$K$6:$K$27,"WON")+COUNTIFS(Selections!$C$6:$C$27,"Bundesliga",Selections!$K$6:$K$27,"LOST")) -> 1 | H9: =IF((COUNTIFS(Selections!$C$6:$C$27,"Bundesliga",Selections!$K$6:$K$27,"WON")+COUNTIFS(Selections!$C$6:$C$27,"Bundesliga",Selections!$K$6:$K$27,"LOST"))=0,"n.a.",COUNTIFS(Selections!$C$6:$C$27,"Bundesliga",Selections!$K$6:$K$27,"WON")/(COUNTIFS(Selections!$C$6:$C$27,"Bundesliga",Selections!$K$6:$K$27,"WON")+COUNTIFS(Selections!$C$6:$C$27,"Bundesliga",Selections!$K$6:$K$27,"LOST"))) -> n.a. | I9: =SUMIFS(Selections!$M$6:$M$27,Selections!$C$6:$C$27,"Bundesliga") -> 0 | J9: =SUMIFS(Selections!$N$6:$N$27,Selections!$C$6:$C$27,"Bundesliga") -> 0 | K9: =IF(SUMIFS(Selections!$M$6:$M$27,Selections!$C$6:$C$27,"Bundesliga")=0,"n.a.",SUMIFS(Selections!$N$6:$N$27,Selections!$C$6:$C$27,"Bundesliga")/SUMIFS(Selections!$M$6:$M$27,Selections!$C$6:$C$27,"Bundesliga")) -> n.a. | L9: =IF(SUMIFS(Selections!$T$6:$T$27,Selections!$C$6:$C$27,"Bundesliga")=0,"n.a.",SUMIFS(Selections!$O$6:$O$27,Selections!$C$6:$C$27,"Bundesliga")/SUMIFS(Selections!$T$6:$T$27,Selections!$C$6:$C$27,"Bundesliga")) -> n.a. | M9: =IF(SUMIFS(Selections!$T$6:$T$27,Selections!$C$6:$C$27,"Bundesliga")=0,"n.a.",SUMIFS(Selections!$S$6:$S$27,Selections!$C$6:$C$27,"Bundesliga")/SUMIFS(Selections!$T$6:$T$27,Selections!$C$6:$C$27,"Bundesliga")) -> n.a. | N9: =IF(SUMIFS(Selections!$T$6:$T$27,Selections!$C$6:$C$27,"Bundesliga")=0,"n.a.",(SUMIFS(Selections!$L$6:$L$27,Selections!$C$6:$C$27,"Bundesliga",Selections!$T$6:$T$27,1))/SUMIFS(Selections!$T$6:$T$27,Selections!$C$6:$C$27,"Bundesliga")) -> n.a. | O9: =IF(SUMIFS(Selections!$T$6:$T$27,Selections!$C$6:$C$27,"Bundesliga")=0,"n.a.",(SUMIFS(Selections!$S$6:$S$27,Selections!$C$6:$C$27,"Bundesliga")-(SUMIFS(Selections!$L$6:$L$27,Selections!$C$6:$C$27,"Bundesliga",Selections!$T$6:$T$27,1)))/SUMIFS(Selections!$T$6:$T$27,Selections!$C$6:$C$27,"Bundesliga")) -> n.a. | P9: =SUMIFS(Selections!$T$6:$T$27,Selections!$C$6:$C$27,"Bundesliga") -> 0 | Q9: =IF(P9<30,"Collect more scored forecasts (n="&P9&").",IF(O9>0.1,"Review overconfidence on a future holdout.",IF(K9<0,"Review prices and EV on a future holdout.","Continue forward testing. No automatic model change."))) -> Collect more scored forecasts (n=0).
A10: League | B10: La Liga | C10: =COUNTIFS(Selections!$C$6:$C$27,"La Liga") -> 7 | D10: =(COUNTIFS(Selections!$C$6:$C$27,"La Liga",Selections!$K$6:$K$27,"WON")+COUNTIFS(Selections!$C$6:$C$27,"La Liga",Selections!$K$6:$K$27,"LOST")) -> 2 | E10: =COUNTIFS(Selections!$C$6:$C$27,"La Liga",Selections!$K$6:$K$27,"WON") -> 2 | F10: =COUNTIFS(Selections!$C$6:$C$27,"La Liga",Selections!$K$6:$K$27,"LOST") -> 0 | G10: =COUNTIFS(Selections!$C$6:$C$27,"La Liga")-(COUNTIFS(Selections!$C$6:$C$27,"La Liga",Selections!$K$6:$K$27,"WON")+COUNTIFS(Selections!$C$6:$C$27,"La Liga",Selections!$K$6:$K$27,"LOST")) -> 5 | H10: =IF((COUNTIFS(Selections!$C$6:$C$27,"La Liga",Selections!$K$6:$K$27,"WON")+COUNTIFS(Selections!$C$6:$C$27,"La Liga",Selections!$K$6:$K$27,"LOST"))=0,"n.a.",COUNTIFS(Selections!$C$6:$C$27,"La Liga",Selections!$K$6:$K$27,"WON")/(COUNTIFS(Selections!$C$6:$C$27,"La Liga",Selections!$K$6:$K$27,"WON")+COUNTIFS(Selections!$C$6:$C$27,"La Liga",Selections!$K$6:$K$27,"LOST"))) -> 1 | I10: =SUMIFS(Selections!$M$6:$M$27,Selections!$C$6:$C$27,"La Liga") -> 2 | J10: =SUMIFS(Selections!$N$6:$N$27,Selections!$C$6:$C$27,"La Liga") -> 0.58 | K10: =IF(SUMIFS(Selections!$M$6:$M$27,Selections!$C$6:$C$27,"La Liga")=0,"n.a.",SUMIFS(Selections!$N$6:$N$27,Selections!$C$6:$C$27,"La Liga")/SUMIFS(Selections!$M$6:$M$27,Selections!$C$6:$C$27,"La Liga")) -> 0.29 | L10: =IF(SUMIFS(Selections!$T$6:$T$27,Selections!$C$6:$C$27,"La Liga")=0,"n.a.",SUMIFS(Selections!$O$6:$O$27,Selections!$C$6:$C$27,"La Liga")/SUMIFS(Selections!$T$6:$T$27,Selections!$C$6:$C$27,"La Liga")) -> 0.028808603 | M10: =IF(SUMIFS(Selections!$T$6:$T$27,Selections!$C$6:$C$27,"La Liga")=0,"n.a.",SUMIFS(Selections!$S$6:$S$27,Selections!$C$6:$C$27,"La Liga")/SUMIFS(Selections!$T$6:$T$27,Selections!$C$6:$C$27,"La Liga")) -> 0.84077105 | N10: =IF(SUMIFS(Selections!$T$6:$T$27,Selections!$C$6:$C$27,"La Liga")=0,"n.a.",(SUMIFS(Selections!$L$6:$L$27,Selections!$C$6:$C$27,"La Liga",Selections!$T$6:$T$27,1))/SUMIFS(Selections!$T$6:$T$27,Selections!$C$6:$C$27,"La Liga")) -> 1 | O10: =IF(SUMIFS(Selections!$T$6:$T$27,Selections!$C$6:$C$27,"La Liga")=0,"n.a.",(SUMIFS(Selections!$S$6:$S$27,Selections!$C$6:$C$27,"La Liga")-(SUMIFS(Selections!$L$6:$L$27,Selections!$C$6:$C$27,"La Liga",Selections!$T$6:$T$27,1)))/SUMIFS(Selections!$T$6:$T$27,Selections!$C$6:$C$27,"La Liga")) -> -0.15922895 | P10: =SUMIFS(Selections!$T$6:$T$27,Selections!$C$6:$C$27,"La Liga") -> 2 | Q10: =IF(P10<30,"Collect more scored forecasts (n="&P10&").",IF(O10>0.1,"Review overconfidence on a future holdout.",IF(K10<0,"Review prices and EV on a future holdout.","Continue forward testing. No automatic model change."))) -> Collect more scored forecasts (n=2).
A11: League | B11: Premier League | C11: =COUNTIFS(Selections!$C$6:$C$27,"Premier League") -> 6 | D11: =(COUNTIFS(Selections!$C$6:$C$27,"Premier League",Selections!$K$6:$K$27,"WON")+COUNTIFS(Selections!$C$6:$C$27,"Premier League",Selections!$K$6:$K$27,"LOST")) -> 3 | E11: =COUNTIFS(Selections!$C$6:$C$27,"Premier League",Selections!$K$6:$K$27,"WON") -> 0 | F11: =COUNTIFS(Selections!$C$6:$C$27,"Premier League",Selections!$K$6:$K$27,"LOST") -> 3 | G11: =COUNTIFS(Selections!$C$6:$C$27,"Premier League")-(COUNTIFS(Selections!$C$6:$C$27,"Premier League",Selections!$K$6:$K$27,"WON")+COUNTIFS(Selections!$C$6:$C$27,"Premier League",Selections!$K$6:$K$27,"LOST")) -> 3 | H11: =IF((COUNTIFS(Selections!$C$6:$C$27,"Premier League",Selections!$K$6:$K$27,"WON")+COUNTIFS(Selections!$C$6:$C$27,"Premier League",Selections!$K$6:$K$27,"LOST"))=0,"n.a.",COUNTIFS(Selections!$C$6:$C$27,"Premier League",Selections!$K$6:$K$27,"WON")/(COUNTIFS(Selections!$C$6:$C$27,"Premier League",Selections!$K$6:$K$27,"WON")+COUNTIFS(Selections!$C$6:$C$27,"Premier League",Selections!$K$6:$K$27,"LOST"))) -> 0 | I11: =SUMIFS(Selections!$M$6:$M$27,Selections!$C$6:$C$27,"Premier League") -> 3 | J11: =SUMIFS(Selections!$N$6:$N$27,Selections!$C$6:$C$27,"Premier League") -> -3 | K11: =IF(SUMIFS(Selections!$M$6:$M$27,Selections!$C$6:$C$27,"Premier League")=0,"n.a.",SUMIFS(Selections!$N$6:$N$27,Selections!$C$6:$C$27,"Premier League")/SUMIFS(Selections!$M$6:$M$27,Selections!$C$6:$C$27,"Premier League")) -> -1 | L11: =IF(SUMIFS(Selections!$T$6:$T$27,Selections!$C$6:$C$27,"Premier League")=0,"n.a.",SUMIFS(Selections!$O$6:$O$27,Selections!$C$6:$C$27,"Premier League")/SUMIFS(Selections!$T$6:$T$27,Selections!$C$6:$C$27,"Premier League")) -> 0.65503 | M11: =IF(SUMIFS(Selections!$T$6:$T$27,Selections!$C$6:$C$27,"Premier League")=0,"n.a.",SUMIFS(Selections!$S$6:$S$27,Selections!$C$6:$C$27,"Premier League")/SUMIFS(Selections!$T$6:$T$27,Selections!$C$6:$C$27,"Premier League")) -> 0.80845891 | N11: =IF(SUMIFS(Selections!$T$6:$T$27,Selections!$C$6:$C$27,"Premier League")=0,"n.a.",(SUMIFS(Selections!$L$6:$L$27,Selections!$C$6:$C$27,"Premier League",Selections!$T$6:$T$27,1))/SUMIFS(Selections!$T$6:$T$27,Selections!$C$6:$C$27,"Premier League")) -> 0 | O11: =IF(SUMIFS(Selections!$T$6:$T$27,Selections!$C$6:$C$27,"Premier League")=0,"n.a.",(SUMIFS(Selections!$S$6:$S$27,Selections!$C$6:$C$27,"Premier League")-(SUMIFS(Selections!$L$6:$L$27,Selections!$C$6:$C$27,"Premier League",Selections!$T$6:$T$27,1)))/SUMIFS(Selections!$T$6:$T$27,Selections!$C$6:$C$27,"Premier League")) -> 0.80845891 | P11: =SUMIFS(Selections!$T$6:$T$27,Selections!$C$6:$C$27,"Premier League") -> 3 | Q11: =IF(P11<30,"Collect more scored forecasts (n="&P11&").",IF(O11>0.1,"Review overconfidence on a future holdout.",IF(K11<0,"Review prices and EV on a future holdout.","Continue forward testing. No automatic model change."))) -> Collect more scored forecasts (n=3).
A12: League | B12: Serie A | C12: =COUNTIFS(Selections!$C$6:$C$27,"Serie A") -> 3 | D12: =(COUNTIFS(Selections!$C$6:$C$27,"Serie A",Selections!$K$6:$K$27,"WON")+COUNTIFS(Selections!$C$6:$C$27,"Serie A",Selections!$K$6:$K$27,"LOST")) -> 2 | E12: =COUNTIFS(Selections!$C$6:$C$27,"Serie A",Selections!$K$6:$K$27,"WON") -> 2 | F12: =COUNTIFS(Selections!$C$6:$C$27,"Serie A",Selections!$K$6:$K$27,"LOST") -> 0 | G12: =COUNTIFS(Selections!$C$6:$C$27,"Serie A")-(COUNTIFS(Selections!$C$6:$C$27,"Serie A",Selections!$K$6:$K$27,"WON")+COUNTIFS(Selections!$C$6:$C$27,"Serie A",Selections!$K$6:$K$27,"LOST")) -> 1 | H12: =IF((COUNTIFS(Selections!$C$6:$C$27,"Serie A",Selections!$K$6:$K$27,"WON")+COUNTIFS(Selections!$C$6:$C$27,"Serie A",Selections!$K$6:$K$27,"LOST"))=0,"n.a.",COUNTIFS(Selections!$C$6:$C$27,"Serie A",Selections!$K$6:$K$27,"WON")/(COUNTIFS(Selections!$C$6:$C$27,"Serie A",Selections!$K$6:$K$27,"WON")+COUNTIFS(Selections!$C$6:$C$27,"Serie A",Selections!$K$6:$K$27,"LOST"))) -> 1 | I12: =SUMIFS(Selections!$M$6:$M$27,Selections!$C$6:$C$27,"Serie A") -> 2 | J12: =SUMIFS(Selections!$N$6:$N$27,Selections!$C$6:$C$27,"Serie A") -> 0.91 | K12: =IF(SUMIFS(Selections!$M$6:$M$27,Selections!$C$6:$C$27,"Serie A")=0,"n.a.",SUMIFS(Selections!$N$6:$N$27,Selections!$C$6:$C$27,"Serie A")/SUMIFS(Selections!$M$6:$M$27,Selections!$C$6:$C$27,"Serie A")) -> 0.455 | L12: =IF(SUMIFS(Selections!$T$6:$T$27,Selections!$C$6:$C$27,"Serie A")=0,"n.a.",SUMIFS(Selections!$O$6:$O$27,Selections!$C$6:$C$27,"Serie A")/SUMIFS(Selections!$T$6:$T$27,Selections!$C$6:$C$27,"Serie A")) -> 0.071193355 | M12: =IF(SUMIFS(Selections!$T$6:$T$27,Selections!$C$6:$C$27,"Serie A")=0,"n.a.",SUMIFS(Selections!$S$6:$S$27,Selections!$C$6:$C$27,"Serie A")/SUMIFS(Selections!$T$6:$T$27,Selections!$C$6:$C$27,"Serie A")) -> 0.73935409 | N12: =IF(SUMIFS(Selections!$T$6:$T$27,Selections!$C$6:$C$27,"Serie A")=0,"n.a.",(SUMIFS(Selections!$L$6:$L$27,Selections!$C$6:$C$27,"Serie A",Selections!$T$6:$T$27,1))/SUMIFS(Selections!$T$6:$T$27,Selections!$C$6:$C$27,"Serie A")) -> 1 | O12: =IF(SUMIFS(Selections!$T$6:$T$27,Selections!$C$6:$C$27,"Serie A")=0,"n.a.",(SUMIFS(Selections!$S$6:$S$27,Selections!$C$6:$C$27,"Serie A")-(SUMIFS(Selections!$L$6:$L$27,Selections!$C$6:$C$27,"Serie A",Selections!$T$6:$T$27,1)))/SUMIFS(Selections!$T$6:$T$27,Selections!$C$6:$C$27,"Serie A")) -> -0.26064591 | P12: =SUMIFS(Selections!$T$6:$T$27,Selections!$C$6:$C$27,"Serie A") -> 2 | Q12: =IF(P12<30,"Collect more scored forecasts (n="&P12&").",IF(O12>0.1,"Review overconfidence on a future holdout.",IF(K12<0,"Review prices and EV on a future holdout.","Continue forward testing. No automatic model change."))) -> Collect more scored forecasts (n=2).
A13: League | B13: UEFA Champions League | C13: =COUNTIFS(Selections!$C$6:$C$27,"UEFA Champions League") -> 5 | D13: =(COUNTIFS(Selections!$C$6:$C$27,"UEFA Champions League",Selections!$K$6:$K$27,"WON")+COUNTIFS(Selections!$C$6:$C$27,"UEFA Champions League",Selections!$K$6:$K$27,"LOST")) -> 4 | E13: =COUNTIFS(Selections!$C$6:$C$27,"UEFA Champions League",Selections!$K$6:$K$27,"WON") -> 4 | F13: =COUNTIFS(Selections!$C$6:$C$27,"UEFA Champions League",Selections!$K$6:$K$27,"LOST") -> 0 | G13: =COUNTIFS(Selections!$C$6:$C$27,"UEFA Champions League")-(COUNTIFS(Selections!$C$6:$C$27,"UEFA Champions League",Selections!$K$6:$K$27,"WON")+COUNTIFS(Selections!$C$6:$C$27,"UEFA Champions League",Selections!$K$6:$K$27,"LOST")) -> 1 | H13: =IF((COUNTIFS(Selections!$C$6:$C$27,"UEFA Champions League",Selections!$K$6:$K$27,"WON")+COUNTIFS(Selections!$C$6:$C$27,"UEFA Champions League",Selections!$K$6:$K$27,"LOST"))=0,"n.a.",COUNTIFS(Selections!$C$6:$C$27,"UEFA Champions League",Selections!$K$6:$K$27,"WON")/(COUNTIFS(Selections!$C$6:$C$27,"UEFA Champions League",Selections!$K$6:$K$27,"WON")+COUNTIFS(Selections!$C$6:$C$27,"UEFA Champions League",Selections!$K$6:$K$27,"LOST"))) -> 1 | I13: =SUMIFS(Selections!$M$6:$M$27,Selections!$C$6:$C$27,"UEFA Champions League") -> 4 | J13: =SUMIFS(Selections!$N$6:$N$27,Selections!$C$6:$C$27,"UEFA Champions League") -> 1.62 | K13: =IF(SUMIFS(Selections!$M$6:$M$27,Selections!$C$6:$C$27,"UEFA Champions League")=0,"n.a.",SUMIFS(Selections!$N$6:$N$27,Selections!$C$6:$C$27,"UEFA Champions League")/SUMIFS(Selections!$M$6:$M$27,Selections!$C$6:$C$27,"UEFA Champions League")) -> 0.405 | L13: =IF(SUMIFS(Selections!$T$6:$T$27,Selections!$C$6:$C$27,"UEFA Champions League")=0,"n.a.",SUMIFS(Selections!$O$6:$O$27,Selections!$C$6:$C$27,"UEFA Champions League")/SUMIFS(Selections!$T$6:$T$27,Selections!$C$6:$C$27,"UEFA Champions League")) -> 0.052539426 | M13: =IF(SUMIFS(Selections!$T$6:$T$27,Selections!$C$6:$C$27,"UEFA Champions League")=0,"n.a.",SUMIFS(Selections!$S$6:$S$27,Selections!$C$6:$C$27,"UEFA Champions League")/SUMIFS(Selections!$T$6:$T$27,Selections!$C$6:$C$27,"UEFA Champions League")) -> 0.80716344 | N13: =IF(SUMIFS(Selections!$T$6:$T$27,Selections!$C$6:$C$27,"UEFA Champions League")=0,"n.a.",(SUMIFS(Selections!$L$6:$L$27,Selections!$C$6:$C$27,"UEFA Champions League",Selections!$T$6:$T$27,1))/SUMIFS(Selections!$T$6:$T$27,Selections!$C$6:$C$27,"UEFA Champions League")) -> 1 | O13: =IF(SUMIFS(Selections!$T$6:$T$27,Selections!$C$6:$C$27,"UEFA Champions League")=0,"n.a.",(SUMIFS(Selections!$S$6:$S$27,Selections!$C$6:$C$27,"UEFA Champions League")-(SUMIFS(Selections!$L$6:$L$27,Selections!$C$6:$C$27,"UEFA Champions League",Selections!$T$6:$T$27,1)))/SUMIFS(Selections!$T$6:$T$27,Selections!$C$6:$C$27,"UEFA Champions League")) -> -0.19283656 | P13: =SUMIFS(Selections!$T$6:$T$27,Selections!$C$6:$C$27,"UEFA Champions League") -> 4 | Q13: =IF(P13<30,"Collect more scored forecasts (n="&P13&").",IF(O13>0.1,"Review overconfidence on a future holdout.",IF(K13<0,"Review prices and EV on a future holdout.","Continue forward testing. No automatic model change."))) -> Collect more scored forecasts (n=4).
A14: Market | B14: Away win | C14: =COUNTIFS(Selections!$E$6:$E$27,"Away win") -> 1 | D14: =(COUNTIFS(Selections!$E$6:$E$27,"Away win",Selections!$K$6:$K$27,"WON")+COUNTIFS(Selections!$E$6:$E$27,"Away win",Selections!$K$6:$K$27,"LOST")) -> 0 | E14: =COUNTIFS(Selections!$E$6:$E$27,"Away win",Selections!$K$6:$K$27,"WON") -> 0 | F14: =COUNTIFS(Selections!$E$6:$E$27,"Away win",Selections!$K$6:$K$27,"LOST") -> 0 | G14: =COUNTIFS(Selections!$E$6:$E$27,"Away win")-(COUNTIFS(Selections!$E$6:$E$27,"Away win",Selections!$K$6:$K$27,"WON")+COUNTIFS(Selections!$E$6:$E$27,"Away win",Selections!$K$6:$K$27,"LOST")) -> 1 | H14: =IF((COUNTIFS(Selections!$E$6:$E$27,"Away win",Selections!$K$6:$K$27,"WON")+COUNTIFS(Selections!$E$6:$E$27,"Away win",Selections!$K$6:$K$27,"LOST"))=0,"n.a.",COUNTIFS(Selections!$E$6:$E$27,"Away win",Selections!$K$6:$K$27,"WON")/(COUNTIFS(Selections!$E$6:$E$27,"Away win",Selections!$K$6:$K$27,"WON")+COUNTIFS(Selections!$E$6:$E$27,"Away win",Selections!$K$6:$K$27,"LOST"))) -> n.a. | I14: =SUMIFS(Selections!$M$6:$M$27,Selections!$E$6:$E$27,"Away win") -> 0 | J14: =SUMIFS(Selections!$N$6:$N$27,Selections!$E$6:$E$27,"Away win") -> 0 | K14: =IF(SUMIFS(Selections!$M$6:$M$27,Selections!$E$6:$E$27,"Away win")=0,"n.a.",SUMIFS(Selections!$N$6:$N$27,Selections!$E$6:$E$27,"Away win")/SUMIFS(Selections!$M$6:$M$27,Selections!$E$6:$E$27,"Away win")) -> n.a. | L14: =IF(SUMIFS(Selections!$T$6:$T$27,Selections!$E$6:$E$27,"Away win")=0,"n.a.",SUMIFS(Selections!$O$6:$O$27,Selections!$E$6:$E$27,"Away win")/SUMIFS(Selections!$T$6:$T$27,Selections!$E$6:$E$27,"Away win")) -> n.a. | M14: =IF(SUMIFS(Selections!$T$6:$T$27,Selections!$E$6:$E$27,"Away win")=0,"n.a.",SUMIFS(Selections!$S$6:$S$27,Selections!$E$6:$E$27,"Away win")/SUMIFS(Selections!$T$6:$T$27,Selections!$E$6:$E$27,"Away win")) -> n.a. | N14: =IF(SUMIFS(Selections!$T$6:$T$27,Selections!$E$6:$E$27,"Away win")=0,"n.a.",(SUMIFS(Selections!$L$6:$L$27,Selections!$E$6:$E$27,"Away win",Selections!$T$6:$T$27,1))/SUMIFS(Selections!$T$6:$T$27,Selections!$E$6:$E$27,"Away win")) -> n.a. | O14: =IF(SUMIFS(Selections!$T$6:$T$27,Selections!$E$6:$E$27,"Away win")=0,"n.a.",(SUMIFS(Selections!$S$6:$S$27,Selections!$E$6:$E$27,"Away win")-(SUMIFS(Selections!$L$6:$L$27,Selections!$E$6:$E$27,"Away win",Selections!$T$6:$T$27,1)))/SUMIFS(Selections!$T$6:$T$27,Selections!$E$6:$E$27,"Away win")) -> n.a. | P14: =SUMIFS(Selections!$T$6:$T$27,Selections!$E$6:$E$27,"Away win") -> 0 | Q14: =IF(P14<30,"Collect more scored forecasts (n="&P14&").",IF(O14>0.1,"Review overconfidence on a future holdout.",IF(K14<0,"Review prices and EV on a future holdout.","Continue forward testing. No automatic model change."))) -> Collect more scored forecasts (n=0).
A15: Market | B15: Both Teams to Score - Yes | C15: =COUNTIFS(Selections!$E$6:$E$27,"Both Teams to Score - Yes") -> 1 | D15: =(COUNTIFS(Selections!$E$6:$E$27,"Both Teams to Score - Yes",Selections!$K$6:$K$27,"WON")+COUNTIFS(Selections!$E$6:$E$27,"Both Teams to Score - Yes",Selections!$K$6:$K$27,"LOST")) -> 1 | E15: =COUNTIFS(Selections!$E$6:$E$27,"Both Teams to Score - Yes",Selections!$K$6:$K$27,"WON") -> 1 | F15: =COUNTIFS(Selections!$E$6:$E$27,"Both Teams to Score - Yes",Selections!$K$6:$K$27,"LOST") -> 0 | G15: =COUNTIFS(Selections!$E$6:$E$27,"Both Teams to Score - Yes")-(COUNTIFS(Selections!$E$6:$E$27,"Both Teams to Score - Yes",Selections!$K$6:$K$27,"WON")+COUNTIFS(Selections!$E$6:$E$27,"Both Teams to Score - Yes",Selections!$K$6:$K$27,"LOST")) -> 0 | H15: =IF((COUNTIFS(Selections!$E$6:$E$27,"Both Teams to Score - Yes",Selections!$K$6:$K$27,"WON")+COUNTIFS(Selections!$E$6:$E$27,"Both Teams to Score - Yes",Selections!$K$6:$K$27,"LOST"))=0,"n.a.",COUNTIFS(Selections!$E$6:$E$27,"Both Teams to Score - Yes",Selections!$K$6:$K$27,"WON")/(COUNTIFS(Selections!$E$6:$E$27,"Both Teams to Score - Yes",Selections!$K$6:$K$27,"WON")+COUNTIFS(Selections!$E$6:$E$27,"Both Teams to Score - Yes",Selections!$K$6:$K$27,"LOST"))) -> 1 | I15: =SUMIFS(Selections!$M$6:$M$27,Selections!$E$6:$E$27,"Both Teams to Score - Yes") -> 1 | J15: =SUMIFS(Selections!$N$6:$N$27,Selections!$E$6:$E$27,"Both Teams to Score - Yes") -> 0.49 | K15: =IF(SUMIFS(Selections!$M$6:$M$27,Selections!$E$6:$E$27,"Both Teams to Score - Yes")=0,"n.a.",SUMIFS(Selections!$N$6:$N$27,Selections!$E$6:$E$27,"Both Teams to Score - Yes")/SUMIFS(Selections!$M$6:$M$27,Selections!$E$6:$E$27,"Both Teams to Score - Yes")) -> 0.49 | L15: =IF(SUMIFS(Selections!$T$6:$T$27,Selections!$E$6:$E$27,"Both Teams to Score - Yes")=0,"n.a.",SUMIFS(Selections!$O$6:$O$27,Selections!$E$6:$E$27,"Both Teams to Score - Yes")/SUMIFS(Selections!$T$6:$T$27,Selections!$E$6:$E$27,"Both Teams to Score - Yes")) -> 0.086628456 | M15: =IF(SUMIFS(Selections!$T$6:$T$27,Selections!$E$6:$E$27,"Both Teams to Score - Yes")=0,"n.a.",SUMIFS(Selections!$S$6:$S$27,Selections!$E$6:$E$27,"Both Teams to Score - Yes")/SUMIFS(Selections!$T$6:$T$27,Selections!$E$6:$E$27,"Both Teams to Score - Yes")) -> 0.70567288 | N15: =IF(SUMIFS(Selections!$T$6:$T$27,Selections!$E$6:$E$27,"Both Teams to Score - Yes")=0,"n.a.",(SUMIFS(Selections!$L$6:$L$27,Selections!$E$6:$E$27,"Both Teams to Score - Yes",Selections!$T$6:$T$27,1))/SUMIFS(Selections!$T$6:$T$27,Selections!$E$6:$E$27,"Both Teams to Score - Yes")) -> 1 | O15: =IF(SUMIFS(Selections!$T$6:$T$27,Selections!$E$6:$E$27,"Both Teams to Score - Yes")=0,"n.a.",(SUMIFS(Selections!$S$6:$S$27,Selections!$E$6:$E$27,"Both Teams to Score - Yes")-(SUMIFS(Selections!$L$6:$L$27,Selections!$E$6:$E$27,"Both Teams to Score - Yes",Selections!$T$6:$T$27,1)))/SUMIFS(Selections!$T$6:$T$27,Selections!$E$6:$E$27,"Both Teams to Score - Yes")) -> -0.29432712 | P15: =SUMIFS(Selections!$T$6:$T$27,Selections!$E$6:$E$27,"Both Teams to Score - Yes") -> 1 | Q15: =IF(P15<30,"Collect more scored forecasts (n="&P15&").",IF(O15>0.1,"Review overconfidence on a future holdout.",IF(K15<0,"Review prices and EV on a future holdout.","Continue forward testing. No automatic model change."))) -> Collect more scored forecasts (n=1).
A16: Market | B16: Double Chance 1X | C16: =COUNTIFS(Selections!$E$6:$E$27,"Double Chance 1X") -> 1 | D16: =(COUNTIFS(Selections!$E$6:$E$27,"Double Chance 1X",Selections!$K$6:$K$27,"WON")+COUNTIFS(Selections!$E$6:$E$27,"Double Chance 1X",Selections!$K$6:$K$27,"LOST")) -> 0 | E16: =COUNTIFS(Selections!$E$6:$E$27,"Double Chance 1X",Selections!$K$6:$K$27,"WON") -> 0 | F16: =COUNTIFS(Selections!$E$6:$E$27,"Double Chance 1X",Selections!$K$6:$K$27,"LOST") -> 0 | G16: =COUNTIFS(Selections!$E$6:$E$27,"Double Chance 1X")-(COUNTIFS(Selections!$E$6:$E$27,"Double Chance 1X",Selections!$K$6:$K$27,"WON")+COUNTIFS(Selections!$E$6:$E$27,"Double Chance 1X",Selections!$K$6:$K$27,"LOST")) -> 1 | H16: =IF((COUNTIFS(Selections!$E$6:$E$27,"Double Chance 1X",Selections!$K$6:$K$27,"WON")+COUNTIFS(Selections!$E$6:$E$27,"Double Chance 1X",Selections!$K$6:$K$27,"LOST"))=0,"n.a.",COUNTIFS(Selections!$E$6:$E$27,"Double Chance 1X",Selections!$K$6:$K$27,"WON")/(COUNTIFS(Selections!$E$6:$E$27,"Double Chance 1X",Selections!$K$6:$K$27,"WON")+COUNTIFS(Selections!$E$6:$E$27,"Double Chance 1X",Selections!$K$6:$K$27,"LOST"))) -> n.a. | I16: =SUMIFS(Selections!$M$6:$M$27,Selections!$E$6:$E$27,"Double Chance 1X") -> 0 | J16: =SUMIFS(Selections!$N$6:$N$27,Selections!$E$6:$E$27,"Double Chance 1X") -> 0 | K16: =IF(SUMIFS(Selections!$M$6:$M$27,Selections!$E$6:$E$27,"Double Chance 1X")=0,"n.a.",SUMIFS(Selections!$N$6:$N$27,Selections!$E$6:$E$27,"Double Chance 1X")/SUMIFS(Selections!$M$6:$M$27,Selections!$E$6:$E$27,"Double Chance 1X")) -> n.a. | L16: =IF(SUMIFS(Selections!$T$6:$T$27,Selections!$E$6:$E$27,"Double Chance 1X")=0,"n.a.",SUMIFS(Selections!$O$6:$O$27,Selections!$E$6:$E$27,"Double Chance 1X")/SUMIFS(Selections!$T$6:$T$27,Selections!$E$6:$E$27,"Double Chance 1X")) -> n.a. | M16: =IF(SUMIFS(Selections!$T$6:$T$27,Selections!$E$6:$E$27,"Double Chance 1X")=0,"n.a.",SUMIFS(Selections!$S$6:$S$27,Selections!$E$6:$E$27,"Double Chance 1X")/SUMIFS(Selections!$T$6:$T$27,Selections!$E$6:$E$27,"Double Chance 1X")) -> n.a. | N16: =IF(SUMIFS(Selections!$T$6:$T$27,Selections!$E$6:$E$27,"Double Chance 1X")=0,"n.a.",(SUMIFS(Selections!$L$6:$L$27,Selections!$E$6:$E$27,"Double Chance 1X",Selections!$T$6:$T$27,1))/SUMIFS(Selections!$T$6:$T$27,Selections!$E$6:$E$27,"Double Chance 1X")) -> n.a. | O16: =IF(SUMIFS(Selections!$T$6:$T$27,Selections!$E$6:$E$27,"Double Chance 1X")=0,"n.a.",(SUMIFS(Selections!$S$6:$S$27,Selections!$E$6:$E$27,"Double Chance 1X")-(SUMIFS(Selections!$L$6:$L$27,Selections!$E$6:$E$27,"Double Chance 1X",Selections!$T$6:$T$27,1)))/SUMIFS(Selections!$T$6:$T$27,Selections!$E$6:$E$27,"Double Chance 1X")) -> n.a. | P16: =SUMIFS(Selections!$T$6:$T$27,Selections!$E$6:$E$27,"Double Chance 1X") -> 0 | Q16: =IF(P16<30,"Collect more scored forecasts (n="&P16&").",IF(O16>0.1,"Review overconfidence on a future holdout.",IF(K16<0,"Review prices and EV on a future holdout.","Continue forward testing. No automatic model change."))) -> Collect more scored forecasts (n=0).
A17: Market | B17: Home win | C17: =COUNTIFS(Selections!$E$6:$E$27,"Home win") -> 4 | D17: =(COUNTIFS(Selections!$E$6:$E$27,"Home win",Selections!$K$6:$K$27,"WON")+COUNTIFS(Selections!$E$6:$E$27,"Home win",Selections!$K$6:$K$27,"LOST")) -> 2 | E17: =COUNTIFS(Selections!$E$6:$E$27,"Home win",Selections!$K$6:$K$27,"WON") -> 2 | F17: =COUNTIFS(Selections!$E$6:$E$27,"Home win",Selections!$K$6:$K$27,"LOST") -> 0 | G17: =COUNTIFS(Selections!$E$6:$E$27,"Home win")-(COUNTIFS(Selections!$E$6:$E$27,"Home win",Selections!$K$6:$K$27,"WON")+COUNTIFS(Selections!$E$6:$E$27,"Home win",Selections!$K$6:$K$27,"LOST")) -> 2 | H17: =IF((COUNTIFS(Selections!$E$6:$E$27,"Home win",Selections!$K$6:$K$27,"WON")+COUNTIFS(Selections!$E$6:$E$27,"Home win",Selections!$K$6:$K$27,"LOST"))=0,"n.a.",COUNTIFS(Selections!$E$6:$E$27,"Home win",Selections!$K$6:$K$27,"WON")/(COUNTIFS(Selections!$E$6:$E$27,"Home win",Selections!$K$6:$K$27,"WON")+COUNTIFS(Selections!$E$6:$E$27,"Home win",Selections!$K$6:$K$27,"LOST"))) -> 1 | I17: =SUMIFS(Selections!$M$6:$M$27,Selections!$E$6:$E$27,"Home win") -> 2 | J17: =SUMIFS(Selections!$N$6:$N$27,Selections!$E$6:$E$27,"Home win") -> 1.37 | K17: =IF(SUMIFS(Selections!$M$6:$M$27,Selections!$E$6:$E$27,"Home win")=0,"n.a.",SUMIFS(Selections!$N$6:$N$27,Selections!$E$6:$E$27,"Home win")/SUMIFS(Selections!$M$6:$M$27,Selections!$E$6:$E$27,"Home win")) -> 0.685 | L17: =IF(SUMIFS(Selections!$T$6:$T$27,Selections!$E$6:$E$27,"Home win")=0,"n.a.",SUMIFS(Selections!$O$6:$O$27,Selections!$E$6:$E$27,"Home win")/SUMIFS(Selections!$T$6:$T$27,Selections!$E$6:$E$27,"Home win")) -> 0.10707454 | M17: =IF(SUMIFS(Selections!$T$6:$T$27,Selections!$E$6:$E$27,"Home win")=0,"n.a.",SUMIFS(Selections!$S$6:$S$27,Selections!$E$6:$E$27,"Home win")/SUMIFS(Selections!$T$6:$T$27,Selections!$E$6:$E$27,"Home win")) -> 0.67291177 | N17: =IF(SUMIFS(Selections!$T$6:$T$27,Selections!$E$6:$E$27,"Home win")=0,"n.a.",(SUMIFS(Selections!$L$6:$L$27,Selections!$E$6:$E$27,"Home win",Selections!$T$6:$T$27,1))/SUMIFS(Selections!$T$6:$T$27,Selections!$E$6:$E$27,"Home win")) -> 1 | O17: =IF(SUMIFS(Selections!$T$6:$T$27,Selections!$E$6:$E$27,"Home win")=0,"n.a.",(SUMIFS(Selections!$S$6:$S$27,Selections!$E$6:$E$27,"Home win")-(SUMIFS(Selections!$L$6:$L$27,Selections!$E$6:$E$27,"Home win",Selections!$T$6:$T$27,1)))/SUMIFS(Selections!$T$6:$T$27,Selections!$E$6:$E$27,"Home win")) -> -0.32708823 | P17: =SUMIFS(Selections!$T$6:$T$27,Selections!$E$6:$E$27,"Home win") -> 2 | Q17: =IF(P17<30,"Collect more scored forecasts (n="&P17&").",IF(O17>0.1,"Review overconfidence on a future holdout.",IF(K17<0,"Review prices and EV on a future holdout.","Continue forward testing. No automatic model change."))) -> Collect more scored forecasts (n=2).
A18: Market | B18: Over 1.5 | C18: =COUNTIFS(Selections!$E$6:$E$27,"Over 1.5") -> 9 | D18: =(COUNTIFS(Selections!$E$6:$E$27,"Over 1.5",Selections!$K$6:$K$27,"WON")+COUNTIFS(Selections!$E$6:$E$27,"Over 1.5",Selections!$K$6:$K$27,"LOST")) -> 4 | E18: =COUNTIFS(Selections!$E$6:$E$27,"Over 1.5",Selections!$K$6:$K$27,"WON") -> 4 | F18: =COUNTIFS(Selections!$E$6:$E$27,"Over 1.5",Selections!$K$6:$K$27,"LOST") -> 0 | G18: =COUNTIFS(Selections!$E$6:$E$27,"Over 1.5")-(COUNTIFS(Selections!$E$6:$E$27,"Over 1.5",Selections!$K$6:$K$27,"WON")+COUNTIFS(Selections!$E$6:$E$27,"Over 1.5",Selections!$K$6:$K$27,"LOST")) -> 5 | H18: =IF((COUNTIFS(Selections!$E$6:$E$27,"Over 1.5",Selections!$K$6:$K$27,"WON")+COUNTIFS(Selections!$E$6:$E$27,"Over 1.5",Selections!$K$6:$K$27,"LOST"))=0,"n.a.",COUNTIFS(Selections!$E$6:$E$27,"Over 1.5",Selections!$K$6:$K$27,"WON")/(COUNTIFS(Selections!$E$6:$E$27,"Over 1.5",Selections!$K$6:$K$27,"WON")+COUNTIFS(Selections!$E$6:$E$27,"Over 1.5",Selections!$K$6:$K$27,"LOST"))) -> 1 | I18: =SUMIFS(Selections!$M$6:$M$27,Selections!$E$6:$E$27,"Over 1.5") -> 4 | J18: =SUMIFS(Selections!$N$6:$N$27,Selections!$E$6:$E$27,"Over 1.5") -> 0.97 | K18: =IF(SUMIFS(Selections!$M$6:$M$27,Selections!$E$6:$E$27,"Over 1.5")=0,"n.a.",SUMIFS(Selections!$N$6:$N$27,Selections!$E$6:$E$27,"Over 1.5")/SUMIFS(Selections!$M$6:$M$27,Selections!$E$6:$E$27,"Over 1.5")) -> 0.2425 | L18: =IF(SUMIFS(Selections!$T$6:$T$27,Selections!$E$6:$E$27,"Over 1.5")=0,"n.a.",SUMIFS(Selections!$O$6:$O$27,Selections!$E$6:$E$27,"Over 1.5")/SUMIFS(Selections!$T$6:$T$27,Selections!$E$6:$E$27,"Over 1.5")) -> 0.016985304 | M18: =IF(SUMIFS(Selections!$T$6:$T$27,Selections!$E$6:$E$27,"Over 1.5")=0,"n.a.",SUMIFS(Selections!$S$6:$S$27,Selections!$E$6:$E$27,"Over 1.5")/SUMIFS(Selections!$T$6:$T$27,Selections!$E$6:$E$27,"Over 1.5")) -> 0.88524571 | N18: =IF(SUMIFS(Selections!$T$6:$T$27,Selections!$E$6:$E$27,"Over 1.5")=0,"n.a.",(SUMIFS(Selections!$L$6:$L$27,Selections!$E$6:$E$27,"Over 1.5",Selections!$T$6:$T$27,1))/SUMIFS(Selections!$T$6:$T$27,Selections!$E$6:$E$27,"Over 1.5")) -> 1 | O18: =IF(SUMIFS(Selections!$T$6:$T$27,Selections!$E$6:$E$27,"Over 1.5")=0,"n.a.",(SUMIFS(Selections!$S$6:$S$27,Selections!$E$6:$E$27,"Over 1.5")-(SUMIFS(Selections!$L$6:$L$27,Selections!$E$6:$E$27,"Over 1.5",Selections!$T$6:$T$27,1)))/SUMIFS(Selections!$T$6:$T$27,Selections!$E$6:$E$27,"Over 1.5")) -> -0.11475429 | P18: =SUMIFS(Selections!$T$6:$T$27,Selections!$E$6:$E$27,"Over 1.5") -> 4 | Q18: =IF(P18<30,"Collect more scored forecasts (n="&P18&").",IF(O18>0.1,"Review overconfidence on a future holdout.",IF(K18<0,"Review prices and EV on a future holdout.","Continue forward testing. No automatic model change."))) -> Collect more scored forecasts (n=4).
A19: Market | B19: Under 3.5 | C19: =COUNTIFS(Selections!$E$6:$E$27,"Under 3.5") -> 6 | D19: =(COUNTIFS(Selections!$E$6:$E$27,"Under 3.5",Selections!$K$6:$K$27,"WON")+COUNTIFS(Selections!$E$6:$E$27,"Under 3.5",Selections!$K$6:$K$27,"LOST")) -> 4 | E19: =COUNTIFS(Selections!$E$6:$E$27,"Under 3.5",Selections!$K$6:$K$27,"WON") -> 1 | F19: =COUNTIFS(Selections!$E$6:$E$27,"Under 3.5",Selections!$K$6:$K$27,"LOST") -> 3 | G19: =COUNTIFS(Selections!$E$6:$E$27,"Under 3.5")-(COUNTIFS(Selections!$E$6:$E$27,"Under 3.5",Selections!$K$6:$K$27,"WON")+COUNTIFS(Selections!$E$6:$E$27,"Under 3.5",Selections!$K$6:$K$27,"LOST")) -> 2 | H19: =IF((COUNTIFS(Selections!$E$6:$E$27,"Under 3.5",Selections!$K$6:$K$27,"WON")+COUNTIFS(Selections!$E$6:$E$27,"Under 3.5",Selections!$K$6:$K$27,"LOST"))=0,"n.a.",COUNTIFS(Selections!$E$6:$E$27,"Under 3.5",Selections!$K$6:$K$27,"WON")/(COUNTIFS(Selections!$E$6:$E$27,"Under 3.5",Selections!$K$6:$K$27,"WON")+COUNTIFS(Selections!$E$6:$E$27,"Under 3.5",Selections!$K$6:$K$27,"LOST"))) -> 0.25 | I19: =SUMIFS(Selections!$M$6:$M$27,Selections!$E$6:$E$27,"Under 3.5") -> 4 | J19: =SUMIFS(Selections!$N$6:$N$27,Selections!$E$6:$E$27,"Under 3.5") -> -2.72 | K19: =IF(SUMIFS(Selections!$M$6:$M$27,Selections!$E$6:$E$27,"Under 3.5")=0,"n.a.",SUMIFS(Selections!$N$6:$N$27,Selections!$E$6:$E$27,"Under 3.5")/SUMIFS(Selections!$M$6:$M$27,Selections!$E$6:$E$27,"Under 3.5")) -> -0.68 | L19: =IF(SUMIFS(Selections!$T$6:$T$27,Selections!$E$6:$E$27,"Under 3.5")=0,"n.a.",SUMIFS(Selections!$O$6:$O$27,Selections!$E$6:$E$27,"Under 3.5")/SUMIFS(Selections!$T$6:$T$27,Selections!$E$6:$E$27,"Under 3.5")) -> 0.50163322 | M19: =IF(SUMIFS(Selections!$T$6:$T$27,Selections!$E$6:$E$27,"Under 3.5")=0,"n.a.",SUMIFS(Selections!$S$6:$S$27,Selections!$E$6:$E$27,"Under 3.5")/SUMIFS(Selections!$T$6:$T$27,Selections!$E$6:$E$27,"Under 3.5")) -> 0.80545037 | N19: =IF(SUMIFS(Selections!$T$6:$T$27,Selections!$E$6:$E$27,"Under 3.5")=0,"n.a.",(SUMIFS(Selections!$L$6:$L$27,Selections!$E$6:$E$27,"Under 3.5",Selections!$T$6:$T$27,1))/SUMIFS(Selections!$T$6:$T$27,Selections!$E$6:$E$27,"Under 3.5")) -> 0.25 | O19: =IF(SUMIFS(Selections!$T$6:$T$27,Selections!$E$6:$E$27,"Under 3.5")=0,"n.a.",(SUMIFS(Selections!$S$6:$S$27,Selections!$E$6:$E$27,"Under 3.5")-(SUMIFS(Selections!$L$6:$L$27,Selections!$E$6:$E$27,"Under 3.5",Selections!$T$6:$T$27,1)))/SUMIFS(Selections!$T$6:$T$27,Selections!$E$6:$E$27,"Under 3.5")) -> 0.55545037 | P19: =SUMIFS(Selections!$T$6:$T$27,Selections!$E$6:$E$27,"Under 3.5") -> 4 | Q19: =IF(P19<30,"Collect more scored forecasts (n="&P19&").",IF(O19>0.1,"Review overconfidence on a future holdout.",IF(K19<0,"Review prices and EV on a future holdout.","Continue forward testing. No automatic model change."))) -> Collect more scored forecasts (n=4).
A20: Policy | B20: 72h-all-markets-net-ev15-execution-v7 | C20: =COUNTIFS(Selections!$G$6:$G$27,"72h-all-markets-net-ev15-execution-v7") -> 2 | D20: =(COUNTIFS(Selections!$G$6:$G$27,"72h-all-markets-net-ev15-execution-v7",Selections!$K$6:$K$27,"WON")+COUNTIFS(Selections!$G$6:$G$27,"72h-all-markets-net-ev15-execution-v7",Selections!$K$6:$K$27,"LOST")) -> 0 | E20: =COUNTIFS(Selections!$G$6:$G$27,"72h-all-markets-net-ev15-execution-v7",Selections!$K$6:$K$27,"WON") -> 0 | F20: =COUNTIFS(Selections!$G$6:$G$27,"72h-all-markets-net-ev15-execution-v7",Selections!$K$6:$K$27,"LOST") -> 0 | G20: =COUNTIFS(Selections!$G$6:$G$27,"72h-all-markets-net-ev15-execution-v7")-(COUNTIFS(Selections!$G$6:$G$27,"72h-all-markets-net-ev15-execution-v7",Selections!$K$6:$K$27,"WON")+COUNTIFS(Selections!$G$6:$G$27,"72h-all-markets-net-ev15-execution-v7",Selections!$K$6:$K$27,"LOST")) -> 2 | H20: =IF((COUNTIFS(Selections!$G$6:$G$27,"72h-all-markets-net-ev15-execution-v7",Selections!$K$6:$K$27,"WON")+COUNTIFS(Selections!$G$6:$G$27,"72h-all-markets-net-ev15-execution-v7",Selections!$K$6:$K$27,"LOST"))=0,"n.a.",COUNTIFS(Selections!$G$6:$G$27,"72h-all-markets-net-ev15-execution-v7",Selections!$K$6:$K$27,"WON")/(COUNTIFS(Selections!$G$6:$G$27,"72h-all-markets-net-ev15-execution-v7",Selections!$K$6:$K$27,"WON")+COUNTIFS(Selections!$G$6:$G$27,"72h-all-markets-net-ev15-execution-v7",Selections!$K$6:$K$27,"LOST"))) -> n.a. | I20: =SUMIFS(Selections!$M$6:$M$27,Selections!$G$6:$G$27,"72h-all-markets-net-ev15-execution-v7") -> 0 | J20: =SUMIFS(Selections!$N$6:$N$27,Selections!$G$6:$G$27,"72h-all-markets-net-ev15-execution-v7") -> 0 | K20: =IF(SUMIFS(Selections!$M$6:$M$27,Selections!$G$6:$G$27,"72h-all-markets-net-ev15-execution-v7")=0,"n.a.",SUMIFS(Selections!$N$6:$N$27,Selections!$G$6:$G$27,"72h-all-markets-net-ev15-execution-v7")/SUMIFS(Selections!$M$6:$M$27,Selections!$G$6:$G$27,"72h-all-markets-net-ev15-execution-v7")) -> n.a. | L20: =IF(SUMIFS(Selections!$T$6:$T$27,Selections!$G$6:$G$27,"72h-all-markets-net-ev15-execution-v7")=0,"n.a.",SUMIFS(Selections!$O$6:$O$27,Selections!$G$6:$G$27,"72h-all-markets-net-ev15-execution-v7")/SUMIFS(Selections!$T$6:$T$27,Selections!$G$6:$G$27,"72h-all-markets-net-ev15-execution-v7")) -> n.a. | M20: =IF(SUMIFS(Selections!$T$6:$T$27,Selections!$G$6:$G$27,"72h-all-markets-net-ev15-execution-v7")=0,"n.a.",SUMIFS(Selections!$S$6:$S$27,Selections!$G$6:$G$27,"72h-all-markets-net-ev15-execution-v7")/SUMIFS(Selections!$T$6:$T$27,Selections!$G$6:$G$27,"72h-all-markets-net-ev15-execution-v7")) -> n.a. | N20: =IF(SUMIFS(Selections!$T$6:$T$27,Selections!$G$6:$G$27,"72h-all-markets-net-ev15-execution-v7")=0,"n.a.",(SUMIFS(Selections!$L$6:$L$27,Selections!$G$6:$G$27,"72h-all-markets-net-ev15-execution-v7",Selections!$T$6:$T$27,1))/SUMIFS(Selections!$T$6:$T$27,Selections!$G$6:$G$27,"72h-all-markets-net-ev15-execution-v7")) -> n.a. | O20: =IF(SUMIFS(Selections!$T$6:$T$27,Selections!$G$6:$G$27,"72h-all-markets-net-ev15-execution-v7")=0,"n.a.",(SUMIFS(Selections!$S$6:$S$27,Selections!$G$6:$G$27,"72h-all-markets-net-ev15-execution-v7")-(SUMIFS(Selections!$L$6:$L$27,Selections!$G$6:$G$27,"72h-all-markets-net-ev15-execution-v7",Selections!$T$6:$T$27,1)))/SUMIFS(Selections!$T$6:$T$27,Selections!$G$6:$G$27,"72h-all-markets-net-ev15-execution-v7")) -> n.a. | P20: =SUMIFS(Selections!$T$6:$T$27,Selections!$G$6:$G$27,"72h-all-markets-net-ev15-execution-v7") -> 0 | Q20: =IF(P20<30,"Collect more scored forecasts (n="&P20&").",IF(O20>0.1,"Review overconfidence on a future holdout.",IF(K20<0,"Review prices and EV on a future holdout.","Continue forward testing. No automatic model change."))) -> Collect more scored forecasts (n=0).
A21: Policy | B21: 72h-six-markets-dc12-probability-odds-net-ev15-v9 | C21: =COUNTIFS(Selections!$G$6:$G$27,"72h-six-markets-dc12-probability-odds-net-ev15-v9") -> 1 | D21: =(COUNTIFS(Selections!$G$6:$G$27,"72h-six-markets-dc12-probability-odds-net-ev15-v9",Selections!$K$6:$K$27,"WON")+COUNTIFS(Selections!$G$6:$G$27,"72h-six-markets-dc12-probability-odds-net-ev15-v9",Selections!$K$6:$K$27,"LOST")) -> 0 | E21: =COUNTIFS(Selections!$G$6:$G$27,"72h-six-markets-dc12-probability-odds-net-ev15-v9",Selections!$K$6:$K$27,"WON") -> 0 | F21: =COUNTIFS(Selections!$G$6:$G$27,"72h-six-markets-dc12-probability-odds-net-ev15-v9",Selections!$K$6:$K$27,"LOST") -> 0 | G21: =COUNTIFS(Selections!$G$6:$G$27,"72h-six-markets-dc12-probability-odds-net-ev15-v9")-(COUNTIFS(Selections!$G$6:$G$27,"72h-six-markets-dc12-probability-odds-net-ev15-v9",Selections!$K$6:$K$27,"WON")+COUNTIFS(Selections!$G$6:$G$27,"72h-six-markets-dc12-probability-odds-net-ev15-v9",Selections!$K$6:$K$27,"LOST")) -> 1 | H21: =IF((COUNTIFS(Selections!$G$6:$G$27,"72h-six-markets-dc12-probability-odds-net-ev15-v9",Selections!$K$6:$K$27,"WON")+COUNTIFS(Selections!$G$6:$G$27,"72h-six-markets-dc12-probability-odds-net-ev15-v9",Selections!$K$6:$K$27,"LOST"))=0,"n.a.",COUNTIFS(Selections!$G$6:$G$27,"72h-six-markets-dc12-probability-odds-net-ev15-v9",Selections!$K$6:$K$27,"WON")/(COUNTIFS(Selections!$G$6:$G$27,"72h-six-markets-dc12-probability-odds-net-ev15-v9",Selections!$K$6:$K$27,"WON")+COUNTIFS(Selections!$G$6:$G$27,"72h-six-markets-dc12-probability-odds-net-ev15-v9",Selections!$K$6:$K$27,"LOST"))) -> n.a. | I21: =SUMIFS(Selections!$M$6:$M$27,Selections!$G$6:$G$27,"72h-six-markets-dc12-probability-odds-net-ev15-v9") -> 0 | J21: =SUMIFS(Selections!$N$6:$N$27,Selections!$G$6:$G$27,"72h-six-markets-dc12-probability-odds-net-ev15-v9") -> 0 | K21: =IF(SUMIFS(Selections!$M$6:$M$27,Selections!$G$6:$G$27,"72h-six-markets-dc12-probability-odds-net-ev15-v9")=0,"n.a.",SUMIFS(Selections!$N$6:$N$27,Selections!$G$6:$G$27,"72h-six-markets-dc12-probability-odds-net-ev15-v9")/SUMIFS(Selections!$M$6:$M$27,Selections!$G$6:$G$27,"72h-six-markets-dc12-probability-odds-net-ev15-v9")) -> n.a. | L21: =IF(SUMIFS(Selections!$T$6:$T$27,Selections!$G$6:$G$27,"72h-six-markets-dc12-probability-odds-net-ev15-v9")=0,"n.a.",SUMIFS(Selections!$O$6:$O$27,Selections!$G$6:$G$27,"72h-six-markets-dc12-probability-odds-net-ev15-v9")/SUMIFS(Selections!$T$6:$T$27,Selections!$G$6:$G$27,"72h-six-markets-dc12-probability-odds-net-ev15-v9")) -> n.a. | M21: =IF(SUMIFS(Selections!$T$6:$T$27,Selections!$G$6:$G$27,"72h-six-markets-dc12-probability-odds-net-ev15-v9")=0,"n.a.",SUMIFS(Selections!$S$6:$S$27,Selections!$G$6:$G$27,"72h-six-markets-dc12-probability-odds-net-ev15-v9")/SUMIFS(Selections!$T$6:$T$27,Selections!$G$6:$G$27,"72h-six-markets-dc12-probability-odds-net-ev15-v9")) -> n.a. | N21: =IF(SUMIFS(Selections!$T$6:$T$27,Selections!$G$6:$G$27,"72h-six-markets-dc12-probability-odds-net-ev15-v9")=0,"n.a.",(SUMIFS(Selections!$L$6:$L$27,Selections!$G$6:$G$27,"72h-six-markets-dc12-probability-odds-net-ev15-v9",Selections!$T$6:$T$27,1))/SUMIFS(Selections!$T$6:$T$27,Selections!$G$6:$G$27,"72h-six-markets-dc12-probability-odds-net-ev15-v9")) -> n.a. | O21: =IF(SUMIFS(Selections!$T$6:$T$27,Selections!$G$6:$G$27,"72h-six-markets-dc12-probability-odds-net-ev15-v9")=0,"n.a.",(SUMIFS(Selections!$S$6:$S$27,Selections!$G$6:$G$27,"72h-six-markets-dc12-probability-odds-net-ev15-v9")-(SUMIFS(Selections!$L$6:$L$27,Selections!$G$6:$G$27,"72h-six-markets-dc12-probability-odds-net-ev15-v9",Selections!$T$6:$T$27,1)))/SUMIFS(Selections!$T$6:$T$27,Selections!$G$6:$G$27,"72h-six-markets-dc12-probability-odds-net-ev15-v9")) -> n.a. | P21: =SUMIFS(Selections!$T$6:$T$27,Selections!$G$6:$G$27,"72h-six-markets-dc12-probability-odds-net-ev15-v9") -> 0 | Q21: =IF(P21<30,"Collect more scored forecasts (n="&P21&").",IF(O21>0.1,"Review overconfidence on a future holdout.",IF(K21<0,"Review prices and EV on a future holdout.","Continue forward testing. No automatic model change."))) -> Collect more scored forecasts (n=0).
